/opt/miniconda3/envs/NODE_test/lib/python3.12/site-packages/torchvision/io/image.py:14: UserWarning: Failed to load image Python extension: 'dlopen(/opt/miniconda3/envs/NODE_test/lib/python3.12/site-packages/torchvision/image.so, 0x0006): Library not loaded: @rpath/libjpeg.9.dylib
  Referenced from: <367D4265-B20F-34BD-94EB-4F3EE47C385B> /opt/miniconda3/envs/NODE_test/lib/python3.12/site-packages/torchvision/image.so
  Reason: tried: '/opt/miniconda3/envs/NODE_test/lib/python3.12/site-packages/torchvision/../../../libjpeg.9.dylib' (no such file), '/opt/miniconda3/envs/NODE_test/lib/python3.12/site-packages/torchvision/../../../libjpeg.9.dylib' (no such file), '/opt/miniconda3/envs/NODE_test/lib/python3.12/lib-dynload/../../libjpeg.9.dylib' (no such file), '/opt/miniconda3/envs/NODE_test/bin/../lib/libjpeg.9.dylib' (no such file)'If you don't plan on using image functionality from `torchvision.io`, you can ignore this warning. Otherwise, there might be something wrong with your environment. Did you have `libjpeg` or `libpng` installed before building `torchvision` from source?
  warn(
/Users/benjaminmaurel/Documents/Training_Sanofi/notebooks_hands_on/latent_ode/run_models.py
run_models.py --niters 5000 -n 200 -s 40 -l 10 --dataset PK_Tacro --latent-ode --noise-weight 0.01 --max-t 5. --seed 61 --experiment 29488
Couldn't import umap
Sampling dataset of 200 training examples
############## ['200', '186', '4', '192', '178', '9', '82', '134', '138', '38', '104', '191', '146', '122', '59', '10', '19', '144', '189', '46', '29', '114', '85', '197', '55', '105', '91', '179', '187', '158', '72', '148', '57']
165
TensorBoard logs will be saved to: experiments/runs/29488
Traceback (most recent call last):
  File "/Users/benjaminmaurel/Documents/Training_Sanofi/notebooks_hands_on/latent_ode/run_models.py", line 287, in <module>
    batch_dict = utils.get_next_batch(data_obj["train_dataloader"])
                 ^^^^^^^^^^^^^^^^^^^^^^^^^^^^^^^^^^^^^^^^^^^^^^^^^^
  File "/Users/benjaminmaurel/Documents/Training_Sanofi/notebooks_hands_on/latent_ode/lib/utils.py", line 246, in get_next_batch
    data_dict = dataloader.__next__()
                ^^^^^^^^^^^^^^^^^^^^^
  File "/Users/benjaminmaurel/Documents/Training_Sanofi/notebooks_hands_on/latent_ode/lib/utils.py", line 66, in inf_generator
    yield iterator.__next__()
          ^^^^^^^^^^^^^^^^^^^
  File "/opt/miniconda3/envs/NODE_test/lib/python3.12/site-packages/torch/utils/data/dataloader.py", line 701, in __next__
    data = self._next_data()
           ^^^^^^^^^^^^^^^^^
  File "/opt/miniconda3/envs/NODE_test/lib/python3.12/site-packages/torch/utils/data/dataloader.py", line 757, in _next_data
    data = self._dataset_fetcher.fetch(index)  # may raise StopIteration
           ^^^^^^^^^^^^^^^^^^^^^^^^^^^^^^^^^^
  File "/opt/miniconda3/envs/NODE_test/lib/python3.12/site-packages/torch/utils/data/_utils/fetch.py", line 55, in fetch
    return self.collate_fn(data)
           ^^^^^^^^^^^^^^^^^^^^^
  File "/Users/benjaminmaurel/Documents/Training_Sanofi/notebooks_hands_on/latent_ode/lib/parse_datasets.py", line 291, in <lambda>
    collate_fn= lambda batch: collate_fn_tacro(batch, args = args, data_type = "train", device = device))
                              ^^^^^^^^^^^^^^^^^^^^^^^^^^^^^^^^^^^^^^^^^^^^^^^^^^^^^^^^^^^^^^^^^^^^^^^^^^
  File "/Users/benjaminmaurel/Documents/Training_Sanofi/notebooks_hands_on/latent_ode/lib/read_tacro.py", line 1594, in collate_fn_tacro
    auc_be = torch.stack([batch[i][5] for i in range(len(batch))])
             ^^^^^^^^^^^^^^^^^^^^^^^^^^^^^^^^^^^^^^^^^^^^^^^^^^^^^
RuntimeError: stack expects each tensor to be equal size, but got [0] at entry 0 and [1] at entry 1
